const { validationResult } = require('express-validator');

const HttpError = require('../models/http-error');
const User = require('../models/user');

const getUsers = async (req, res, next) => {
    let users;
    try {
        users = await User.find({}, '-password');
    } catch (err) {
        const error = new HttpError(
            'Fetching users failed, please try again later.',
            500
        );
        return next(error);
    }
    res.json({ users: users.map(user => user.toObject({ getters: true })) });
};

const signup = async (req, res, next) => {
    const errors = validationResult(req);
    if (!errors.isEmpty()) {
        return next(
            new HttpError('Invalid inputs passed, please check your data.', 422)
        );
    }
    const { name, email, password } = req.body;

    let existingUser;
    try {
        existingUser = await User.findOne({ email: email });
    } catch (err) {
        const error = new HttpError(
            'Signing up failed, please try again later.',
            500
        );
        return next(error);
    }

    if (existingUser) {
        const error = new HttpError(
            'User exists already, please login instead.',
            422
        );
        return next(error);
    }

    const createdUser = new User({
        name,
        email,
        password,
        orders: [],
        onTable: 0,
        //isAdmin:false
    });

    try {
        await createdUser.save();
    } catch (err) {
        const error = new HttpError(
            'Signing up failed, please try again later.',
            500
        );
        return next(error);
    }

    res.status(201).json({ user: createdUser.toObject({ getters: true }) });
};

const login = async (req, res, next) => {
    const { email, password } = req.body;

    let existingUser;

    try {
        existingUser = await User.findOne({ email: email });
    } catch (err) {
        const error = new HttpError(
            'Loggin in failed, please try again later.',
            500
        );
        return next(error);
    }

    if (!existingUser || existingUser.password !== password) {
        const error = new HttpError(
            'Invalid credentials, could not log you in.',
            401
        );
        return next(error);
    }

    res.json({
        message: 'Logged in!',
        user: existingUser.toObject({ getters: true })
    });
};

const updateTable = async (req, res, next) => {
    const errors = validationResult(req);
    if (!errors.isEmpty()) {
        return next(
            new HttpError('Invalid inputs passed, please check your data.', 422)
        );
    }
    const table = req.body.table;
    const userId = req.params.pid;
    let user;
    try {
        user = await User.findById(userId);
    } catch (err) {
        const error = new HttpError(
            'Something went wrong, could not update order.',
            500
        );
        return next(error);
    }
    user.table = table;

    try {
        await user.save();
    } catch (err) {
        const error = new HttpError(
            'Something went wrong, could not update order.',
            500
        );
        return next(error);
    }

    res.status(200).json({ user: user.toObject({ getters: true }) });
};


exports.getUsers = getUsers;
exports.signup = signup;
exports.login = login;
exports.updateTable = updateTable;
